<?xml version="1.0"?>
<!-- This URDF was automatically created by SolidWorks to URDF Exporter! Originally created by Stephen Brawner (brawner@gmail.com) 
     Commit Version: 1.6.0-4-g7f85cfe  Build Version: 1.6.7995.38578
     For more information, please see http://wiki.ros.org/sw_urdf_exporter -->
<robot xmlns:xacro="http://www.ros.org/wiki/xacro">

  <!-- BASE LINK -->

  <link name="base_link">

  </link>

  <!-- BASE_FOOTPRINT LINK -->

  <joint name="base_footprint_joint" type="fixed">
      <parent link="base_link"/>
      <child link="base_footprint"/>
      <origin xyz="0 0 0" rpy="0 0 0"/>
  </joint>

  <link name="base_footprint">
  </link>

  <!-- CHASSIS LINK -->

  <joint name="chassis_joint" type="fixed">
      <parent link="base_link"/>
      <child link="chassis"/>
      <origin xyz="0 0 0"/>
  </joint>

  <link
    name="chassis">
    <inertial>
      <origin
        xyz="-0.342518803776331 -1.00740975131468E-05 0.646193378336512"
        rpy="0 0 0" />
      <mass
        value="6905.2626850428" />
      <inertia
        ixx="2659.62825070122"
        ixy="-0.15805324903843"
        ixz="662.778571016084"
        iyy="7167.3508600786"
        iyz="0.0119182372416493"
        izz="7690.48218945494" />
    </inertial>
    <visual>
      <origin
        xyz="0 0 0"
        rpy="0 0 0" />
      <geometry>
        <mesh
          filename="file:///home/rozy/thar_ws/src/thar_bot/meshes/base_link.STL" />
      </geometry>
      <material
        name="">
        <color
          rgba="0.792156862745098 0.819607843137255 0.933333333333333 1" />
      </material>
    </visual>
    <collision>
      <origin
        xyz="0 0 0"
        rpy="0 0 0" />
      <geometry>
        <mesh
          filename="file:///home/rozy/thar_ws/src/thar_bot/meshes/base_link.STL" />
      </geometry>
    </collision>
  </link>

  <!-- FRONT LEFT WHEEL LINK -->

  <joint name="frontleftwheeljoint" type="continuous">
    <parent link="chassis"/>
    <child link="front_left_wheel" />
    <origin
      xyz="1.2435 0.76338 0.09753"
      rpy="-1.5708 0 0" />
    <axis
      xyz="0 0 1" />
    <limit
      effort="150"
      velocity="50" />
    <dynamics
      damping="0.1"
      friction="0.2" />
  </joint>
  <link
    name="front_left_wheel">
    <inertial>
      <origin
        xyz="-4.08354209632256E-05 2.45620317269046E-05 0.0405625227917471"
        rpy="0 0 0" />
      <mass
        value="100.43204729493" />
      <inertia
        ixx="6.00052641085959"
        ixy="0.000326803380231443"
        ixz="0.000355730141146499"
        iyy="5.9998640075097"
        iyz="-0.000544177877578132"
        izz="10.3397497457468" />
    </inertial>
    <visual>
      <origin
        xyz="0 0 0"
        rpy="0 0 0" />
      <geometry>
        <mesh
          filename="file:///home/rozy/thar_ws/src/thar_bot/meshes/front_left_wheel.STL" />
      </geometry>
      <material
        name="">
        <color
          rgba="0.792156862745098 0.819607843137255 0.933333333333333 1" />
      </material>
    </visual>
    <collision>
      <origin
        xyz="0 0 0"
        rpy="0 0 0" />
      <geometry>
        <mesh
          filename="file:///home/rozy/thar_ws/src/thar_bot/meshes/front_left_wheel.STL" />
      </geometry>
    </collision>
  </link> 
  
  <!-- FRONT RIGHT WHEEL LINK -->
  <joint
    name="frontrightwheeljoint"
    type="continuous">
    <origin
      xyz="1.2435 -0.76338 0.09753"
      rpy="1.5708 0 0" />
    <parent
      link="chassis"/>
    <child
      link="front_right_wheel" />
    <axis
      xyz="0 0 1" />
    <limit
      effort="150"
      velocity="50" />
    <dynamics
      damping="0.1"
      friction="0.2" />
  </joint>
  <link
    name="front_right_wheel">
    <inertial>
      <origin
        xyz="4.74852119726199E-05 -4.04340829274208E-06 0.040562520171751"
        rpy="0 0 0" />
      <mass
        value="100.43204391536" />
      <inertia
        ixx="6.00013897259221"
        ixy="0.000461886311756949"
        ixz="-0.000559222017905977"
        iyy="6.00025148034712"
        iyz="0.000331555968809409"
        izz="10.3397497647126" />
    </inertial>
    <visual>
      <origin
        xyz="0 0 0"
        rpy="0 0 0" />
      <geometry>
        <mesh
          filename="file:///home/rozy/thar_ws/src/thar_bot/meshes/front_right_wheel.STL" />
      </geometry>
      <material
        name="">
        <color
          rgba="0.792156862745098 0.819607843137255 0.933333333333333 1" />
      </material>
    </visual>
    <collision>
      <origin
        xyz="0 0 0"
        rpy="0 0 0" />
      <geometry>
        <mesh
          filename="file:///home/rozy/thar_ws/src/thar_bot/meshes/front_right_wheel.STL" />
      </geometry>
    </collision>
  </link>


  <!-- BACK LEFT WHEEL LINK -->
  <joint
    name="backleftwheeljoint"
    type="continuous">
    <origin
      xyz="-1.1532 0.76338 0.09753"
      rpy="-1.5708 0 0" />
    <parent
      link="chassis"/>
    <child
      link="back_left_wheel" />
    <axis
      xyz="0 0 1" />
    <limit
      effort="150"
      velocity="50" />
    <dynamics
      damping="0.1"
      friction="0.2" />
  </joint>
  <link
    name="back_left_wheel">
    <inertial>
      <origin
        xyz="-4.0835901066405E-05 2.45613640991738E-05 0.0405625233621417"
        rpy="0 0 0" />
      <mass
        value="100.432047806573" />
      <inertia
        ixx="6.000526414356"
        ixy="0.000326798122321776"
        ixz="0.000355735209098465"
        iyy="5.99986402586364"
        iyz="-0.000544169805288125"
        izz="10.3397497564812" />
    </inertial>
    <visual>
      <origin
        xyz="0 0 0"
        rpy="0 0 0" />
      <geometry>
        <mesh
          filename="file:///home/rozy/thar_ws/src/thar_bot/meshes/back_left_wheel.STL" />
      </geometry>
      <material
        name="">
        <color
          rgba="0.792156862745098 0.819607843137255 0.933333333333333 1" />
      </material>
    </visual>
    <collision>
      <origin
        xyz="0 0 0"
        rpy="0 0 0" />
      <geometry>
        <mesh
          filename="file:///home/rozy/thar_ws/src/thar_bot/meshes/back_left_wheel.STL" />
      </geometry>
    </collision>
  </link>

  <!-- BACK RIGHT WHEEL JOINT -->

  <joint
    name="backrightwheeljoint"
    type="continuous">
    <origin
      xyz="-1.1532 -0.76338 0.09753"
      rpy="1.5708 0 0" />
    <parent
      link="chassis"/>
    <child
      link="back_right_wheel" />
    <axis
      xyz="0 0 1" />
    <limit
      effort="150"
      velocity="50" />
    <dynamics
      damping="0.1"
      friction="0.2" />
  </joint>
  <link
    name="back_right_wheel">
    <inertial>
      <origin
        xyz="4.75996374711407E-05 2.34828695627742E-06 0.0405625210871466"
        rpy="0 0 0" />
      <mass
        value="100.432044739083" />
      <inertia
        ixx="6.00001845271663"
        ixy="0.000430366843601706"
        ixz="-0.000598583859064528"
        iyy="6.00037203810431"
        iyz="0.000253724838825604"
        izz="10.3397497842892" />
    </inertial>
    <visual>
      <origin
        xyz="0 0 0"
        rpy="0 0 0" />
      <geometry>
        <mesh
          filename="file:///home/rozy/thar_ws/src/thar_bot/meshes/back_right_wheel.STL" />
      </geometry>
      <material
        name="">
        <color
          rgba="0.792156862745098 0.819607843137255 0.933333333333333 1" />
      </material>
    </visual>
    <collision>
      <origin
        xyz="0 0 0"
        rpy="0 0 0" />
      <geometry>
        <mesh
          filename="file:///home/rozy/thar_ws/src/thar_bot/meshes/back_right_wheel.STL" />
      </geometry>
    </collision>
  </link>

</robot>
