<?xml version="1.0"?>
<!-- This URDF was automatically created by SolidWorks to URDF Exporter! Originally created by Stephen Brawner (brawner@gmail.com) 
     Commit Version: 1.6.0-4-g7f85cfe  Build Version: 1.6.7995.38578
     For more information, please see http://wiki.ros.org/sw_urdf_exporter -->
<robot xmlns:xacro="http://www.ros.org/wiki/xacro">

  <material
    name="gray">
      <color rgba="0.792156862745098 0.819607843137255 0.933333333333333 1"/>
  </material>

  <xacro:include filename="inertial_macros.xacro"/>

  <!-- BASE LINK -->

  <link name="base_link">

  </link>

  <!-- BASE_FOOTPRINT LINK -->

  <joint name="base_footprint_joint" type="fixed">
      <parent link="base_link"/>
      <child link="base_footprint"/>
      <origin xyz="0 0 0" rpy="0 0 0"/>
  </joint>

  <link name="base_footprint">
  </link>

  <!-- CHASSIS LINK -->

  <joint name="chassis_joint" type="fixed">
      <parent link="base_link"/>
      <child link="chassis"/>
      <origin xyz="0 0 0"/>
  </joint>

  <link
    name="chassis">
    <xacro:inertial_chassis mass="1.5" x="3.844" y="2.064" z="1.466">
            <origin xyz="-0.342518803776331 -1.00740975131468E-05 0.646193378336512" rpy="0 0 0"/>
    </xacro:inertial_chassis>
    <!-- <inertial>
      <origin
        xyz="-0.342518803776331 -1.00740975131468E-05 0.646193378336512"
        rpy="0 0 0" />
      <mass
        value="690.52626850428" />
      <inertia
        ixx="265.962825070122"
        ixy="-0.015805324903843"
        ixz="66.2778571016084"
        iyy="716.73508600786"
        iyz="0.00119182372416493"
        izz="769.048218945494" />
    </inertial> -->
    <visual>
      <origin
        xyz="0 0 0"
        rpy="0 0 0" />
      <geometry>
        <mesh
          filename="file:///home/mahindra/thar_ws/src/thar_bot/meshes/chassisblender.dae" />
      </geometry>
      <material name="gray"/>
    </visual>
    <collision>
      <origin
        xyz="0 0 0"
        rpy="0 0 0" />
      <geometry>
        <mesh
          filename="file:///home/mahindra/thar_ws/src/thar_bot/meshes/base_link.STL" />
      </geometry>
    </collision>
  </link>

  <!-- <gazebo reference="chassis">
    <material>Gazebo/White</material>
  </gazebo> -->



  <!-- FRONT LEFT WHEEL LINK -->

  <joint name="frontleftwheeljoint" type="continuous">
    <parent link="chassis"/>
    <child link="front_left_wheel" />
    <origin
      xyz="1.2435 0.76338 0.09753"
      rpy="-${pi/2} 0 0" />
    <axis
      xyz="0 0 1" />
    <!-- <limit
      effort="2.5"
      velocity="100" />
    <dynamics
      damping="0.09"
      friction="0.05" /> -->
  </joint>
  <link
    name="front_left_wheel">
    <xacro:inertial_wheel mass="0.3" length="0.334" radius="0.398">
            <origin xyz="-4.08354209632256E-05 2.45620317269046E-05 0.0405625227917471" rpy="0 0 0"/>
    </xacro:inertial_wheel>
    <!-- <inertial>
      <origin
        xyz="-4.08354209632256E-05 2.45620317269046E-05 0.0405625227917471"
        rpy="0 0 0" />
      <mass
        value="10.043204729493" />
      <inertia
        ixx="0.600052641085959"
        ixy="0.0000326803380231443"
        ixz="0.0000355730141146499"
        iyy="0.59998640075097"
        iyz="-0.0000544177877578132"
        izz="1.03397497457468" />
    </inertial> -->
    <visual>
      <origin
        xyz="0 0 0"
        rpy="0 0 0" />
      <geometry>
        <mesh
          filename="file:///home/mahindra/thar_ws/src/thar_bot/meshes/wheelblender.dae" />
      </geometry>
      <material
        name="">
        <color
          rgba="0.792156862745098 0.819607843137255 0.933333333333333 1" />
      </material>
    </visual>
    <collision>
      <origin
        xyz="0 0 0"
        rpy="0 0 0" />
      <geometry>
        <mesh
          filename="file:///home/mahindra/thar_ws/src/thar_bot/meshes/front_left_wheel.STL" />
      </geometry>
    </collision>
  </link> 

  <!-- <gazebo reference="front_left_wheel">
    <material>Gazebo/Gray</material>
    <mu1 value="0.001"/>
    <mu2 value="0.001"/>
  </gazebo> -->
  
  <!-- FRONT RIGHT WHEEL LINK -->
  <joint
    name="frontrightwheeljoint"
    type="continuous">
    <origin
      xyz="1.2435 -0.76338 0.09753"
      rpy="${pi/2} 0 0" />
    <parent
      link="chassis"/>
    <child
      link="front_right_wheel" />
    <axis
      xyz="0 0 -1" />
    <!-- <limit
      effort="2.5"
      velocity="100" />
    <dynamics
      damping="0.09"
      friction="0.05" /> -->
  </joint>
  <link
    name="front_right_wheel">
    <xacro:inertial_wheel mass="0.3" length="0.334" radius="0.398">
            <origin xyz="4.74852119726199E-05 -4.04340829274208E-06 0.040562520171751" rpy="0 0 0"/>
    </xacro:inertial_wheel>
    <!-- <inertial>
      <origin
        xyz="4.74852119726199E-05 -4.04340829274208E-06 0.040562520171751"
        rpy="0 0 0" />
      <mass
        value="10.043204391536" />
      <inertia
        ixx="0.600013897259221"
        ixy="0.0000461886311756949"
        ixz="-0.0000559222017905977"
        iyy="0.600025148034712"
        iyz="0.0000331555968809409"
        izz="1.03397497647126" />
    </inertial> -->
    <visual>
      <origin
        xyz="0 0 0"
        rpy="0 0 0" />
      <geometry>
        <mesh
          filename="file:///home/mahindra/thar_ws/src/thar_bot/meshes/wheelblender.dae" />
      </geometry>
      <material
        name="">
        <color
          rgba="0.792156862745098 0.819607843137255 0.933333333333333 1" />
      </material>
    </visual>
    <collision>
      <origin
        xyz="0 0 0"
        rpy="0 0 0" />
      <geometry>
        <mesh
          filename="file:///home/mahindra/thar_ws/src/thar_bot/meshes/front_right_wheel.STL" />
      </geometry>
    </collision>
  </link>

  <!-- <gazebo reference="front_right_wheel">
    <material>Gazebo/Gray</material>
    <mu1 value="0.001"/>
    <mu2 value="0.001"/>
  </gazebo> -->


  <!-- BACK LEFT WHEEL LINK -->
  <joint
    name="backleftwheeljoint"
    type="continuous">
    <origin
      xyz="-1.1532 0.76338 0.09753"
      rpy="-${pi/2} 0 0" />
    <parent
      link="chassis"/>
    <child
      link="back_left_wheel" />
    <axis
      xyz="0 0 1" />
    <!-- <limit
      effort="2.5"
      velocity="100" />
    <dynamics
      damping="0.09"
      friction="0.05" /> -->
  </joint>
  <link
    name="back_left_wheel">
    <xacro:inertial_wheel mass="0.3" length="0.334" radius="0.398">
            <origin xyz="-4.0835901066405E-05 2.45613640991738E-05 0.0405625233621417" rpy="0 0 0"/>
    </xacro:inertial_wheel>
    <!-- <inertial>
      <origin
        xyz="-4.0835901066405E-05 2.45613640991738E-05 0.0405625233621417"
        rpy="0 0 0" />
      <mass
        value="10.0432047806573" />
      <inertia
        ixx="0.6000526414356"
        ixy="0.0000326798122321776"
        ixz="0.0000355735209098465"
        iyy="0.599986402586364"
        iyz="-0.0000544169805288125"
        izz="1.03397497564812" />
    </inertial> -->
    <visual>
      <origin
        xyz="0 0 0"
        rpy="0 0 0" />
      <geometry>
        <mesh
          filename="file:///home/mahindra/thar_ws/src/thar_bot/meshes/wheelblender.dae" />
      </geometry>
      <material
        name="">
        <color
          rgba="0.792156862745098 0.819607843137255 0.933333333333333 1" />
      </material>
    </visual>
    <collision>
      <origin
        xyz="0 0 0"
        rpy="0 0 0" />
      <geometry>
        <mesh
          filename="file:///home/mahindra/thar_ws/src/thar_bot/meshes/back_left_wheel.STL" />
      </geometry>
    </collision>
  </link>

  <!-- <gazebo reference="back_left_wheel">
    <material>Gazebo/Gray</material>
    <mu1 value="0.001"/>
    <mu2 value="0.001"/>
  </gazebo> -->

  <!-- BACK RIGHT WHEEL JOINT -->

  <joint
    name="backrightwheeljoint"
    type="continuous">
    <origin
      xyz="-1.1532 -0.76338 0.09753"
      rpy="${pi/2} 0 0" />
    <parent
      link="chassis"/>
    <child
      link="back_right_wheel" />
    <axis
      xyz="0 0 -1" />
    <!-- <limit
      effort="2.5"
      velocity="100" />
    <dynamics
      damping="0.09"
      friction="0.05" /> -->
  </joint>
  <link
    name="back_right_wheel">
    <xacro:inertial_wheel mass="0.3" length="0.334" radius="0.398">
            <origin xyz="4.75996374711407E-05 2.34828695627742E-06 0.0405625210871466" rpy="0 0 0"/>
    </xacro:inertial_wheel>
    <!-- <inertial>
      <origin
        xyz="4.75996374711407E-05 2.34828695627742E-06 0.0405625210871466"
        rpy="0 0 0" />
      <mass
        value="10.0432044739083" />
      <inertia
        ixx="0.600001845271663"
        ixy="0.0000430366843601706"
        ixz="-0.0000598583859064528"
        iyy="0.600037203810431"
        iyz="0.0000253724838825604"
        izz="0.103397497842892" />
    </inertial> -->
    <visual>
      <origin
        xyz="0 0 0"
        rpy="0 0 0" />
      <geometry>
        <mesh
          filename="file:///home/mahindra/thar_ws/src/thar_bot/meshes/wheelblender.dae" />
      </geometry>
      <material
        name="">
        <!-- <color
          rgba="0.792156862745098 0.819607843137255 0.933333333333333 1" /> -->
        <texture
          filename="file:///home/mahindra/thar_ws/src/thar_bot/textures/Wheel.dae" />
      </material>
    </visual>
    <collision>
      <origin
        xyz="0 0 0"
        rpy="0 0 0" />
      <geometry>
        <mesh
          filename="file:///home/mahindra/thar_ws/src/thar_bot/meshes/back_right_wheel.STL" />
      </geometry>
    </collision>
  </link>

  <!-- SPARE WHEEL -->
  <joint
    name="spare_joint"
    type="fixed">
    <origin
      xyz="-2.0643 -0.010527 0.69561"
      rpy="1.5708 0 1.5708" />
    <parent
      link="base_link" />
    <child
      link="sparewheel" />
    <axis
      xyz="0 0 0" />
  </joint>

  <link
    name="sparewheel">
    <!-- <inertial>
      <origin
        xyz="-3.8298E-05 2.8365E-05 -0.040563"
        rpy="0 0 0" />
      <mass
        value="100.43" />
      <inertia
        ixx="5.9997"
        ixy="-2.2565E-06"
        ixz="-0.00063877"
        iyy="6.0007"
        iyz="0.00012097"
        izz="10.34" />
    </inertial> -->
    <visual>
      <origin
        xyz="0 0 0"
        rpy="0 0 0" />
      <geometry>
        <mesh
          filename="file:///home/mahindra/thar_ws/src/thar_bot/meshes/wheelblender.dae" />
      </geometry>
      <material
        name="wheel">
        <color
          rgba="0.79216 0.81961 0.93333 1" />
        <texture
          filename="file:///home/mahindra/thar_ws/src/thar_bot/meshes/wheelblender.dae" />
      </material>
    </visual>
    <collision>
      <origin
        xyz="0 0 0"
        rpy="0 0 0" />
      <geometry>
        <mesh
          filename="file:///home/mahindra/thar_ws/src/thar_bot/meshes/wheelblender.dae" />
      </geometry>
    </collision>
  </link>



</robot>
